<mujoco model="ant">
  <compiler angle="degree" coordinate="local" inertiafromgeom="true"/>
  <option integrator="RK4" timestep="0.01"/>
  <custom>
    <numeric data="0.0 0.0 0.55 1.0 0.0 0.0 0.0 0.0 1.0 0.0 -1.0 0.0 -1.0 0.0 1.0" name="init_qpos"/>
  </custom>
  <default>
    <joint armature="1" damping="1" limited="true"/>
    <geom conaffinity="0" condim="3" density="5.0" friction="1 0.5 0.5" margin="0.01" rgba="0.8 0.6 0.4 1"/>
  </default>
  <asset>
    <texture builtin="gradient" height="1000" rgb1="1 1 1" rgb2="0 0 0" type="skybox" width="1000"/>
    <texture builtin="flat" height="2278" mark="cross" markrgb="1 1 1" name="texgeom" random="0.01" rgb1="0.8 0.6 0.4" rgb2="0.8 0.6 0.4" type="cube" width="127"/>
    <texture builtin="checker" height="100" name="texplane" rgb1="0 0 0" rgb2="0.8 0.8 0.8" type="2d" width="100"/>
    <material name="geom" texture="texgeom" texuniform="true"/>
    <material name="MatPlane" reflectance="0.5" shininess="1" specular="1" texture="texgeom"/>
  </asset>
  <worldbody>
   <!-- <camera name="top_view" mode="fixed" pos="-20 0 100" xyaxes="1 0 0 0 1 0"/> -->
   <camera name="top_view" mode="fixed" pos="0 0 50" xyaxes="1 0 0 0 1 0"/>
                <!-- <geom conaffinity="1" type="box" name="wall_0_0" size="2.5 2.5 5" pos="-42.5 -17.5 0.5" rgba="0.0 0.0 0.5 1" />
                
                <geom conaffinity="1" type="box" name="wall_0_1" size="2.5 2.5 5" pos="-42.5 -12.5 0.5" rgba="0.0 0.0 0.5 1" />
                
                <geom conaffinity="1" type="box" name="wall_0_2" size="2.5 2.5 5" pos="-42.5 -7.5 0.5" rgba="0.0 0.0 0.5 1" />
                
                <geom conaffinity="1" type="box" name="wall_0_3" size="2.5 2.5 5" pos="-42.5 -2.5 0.5" rgba="0.0 0.0 0.5 1" />
                
                <geom conaffinity="1" type="box" name="wall_0_4" size="2.5 2.5 5" pos="-42.5 2.5 0.5" rgba="0.0 0.0 0.5 1" />
                
                <geom conaffinity="1" type="box" name="wall_0_5" size="2.5 2.5 5" pos="-42.5 7.5 0.5" rgba="0.0 0.0 0.5 1" />
                
                <geom conaffinity="1" type="box" name="wall_0_6" size="2.5 2.5 5" pos="-42.5 12.5 0.5" rgba="0.0 0.0 0.5 1" />
                
                <geom conaffinity="1" type="box" name="wall_0_7" size="2.5 2.5 5" pos="-42.5 17.5 0.5" rgba="0.0 0.0 0.5 1" />
                
                <geom conaffinity="1" type="box" name="wall_0_8" size="2.5 2.5 5" pos="-42.5 22.5 0.5" rgba="0.0 0.0 0.5 1" />
                
                <geom conaffinity="1" type="box" name="wall_0_9" size="2.5 2.5 5" pos="-42.5 27.5 0.5" rgba="0.0 0.0 0.5 1" />
                
                <geom conaffinity="1" type="box" name="wall_0_10" size="2.5 2.5 5" pos="-42.5 32.5 0.5" rgba="0.0 0.0 0.5 1" />
                
                <geom conaffinity="1" type="box" name="wall_1_0" size="2.5 2.5 5" pos="-37.5 -17.5 0.5" rgba="0.0 0.0 0.5 1" />
                
                <geom conaffinity="1" type="box" name="wall_1_1" size="2.5 2.5 5" pos="-37.5 -12.5 0.5" rgba="0.0 0.0 0.5 1" />
                
                <geom conaffinity="1" type="box" name="wall_1_2" size="2.5 2.5 5" pos="-37.5 -7.5 0.5" rgba="0.0 0.0 0.5 1" />
                
                <geom conaffinity="1" type="box" name="wall_1_7" size="2.5 2.5 5" pos="-37.5 17.5 0.5" rgba="0.0 0.0 0.5 1" />
                
                <geom conaffinity="1" type="box" name="wall_1_10" size="2.5 2.5 5" pos="-37.5 32.5 0.5" rgba="0.0 0.0 0.5 1" />
                
                <geom conaffinity="1" type="box" name="wall_2_0" size="2.5 2.5 5" pos="-32.5 -17.5 0.5" rgba="0.0 0.0 0.5 1" />
                
                <geom conaffinity="1" type="box" name="wall_2_1" size="2.5 2.5 5" pos="-32.5 -12.5 0.5" rgba="0.0 0.0 0.5 1" />
                
                <geom conaffinity="1" type="box" name="wall_2_2" size="2.5 2.5 5" pos="-32.5 -7.5 0.5" rgba="0.0 0.0 0.5 1" />
                
                <geom conaffinity="1" type="box" name="wall_2_7" size="2.5 2.5 5" pos="-32.5 17.5 0.5" rgba="0.0 0.0 0.5 1" />
                
                <geom conaffinity="1" type="box" name="wall_2_10" size="2.5 2.5 5" pos="-32.5 32.5 0.5" rgba="0.0 0.0 0.5 1" />
                
                <geom conaffinity="1" type="box" name="wall_3_0" size="2.5 2.5 5" pos="-27.5 -17.5 0.5" rgba="0.0 0.0 0.5 1" />
                
                <geom conaffinity="1" type="box" name="wall_3_1" size="2.5 2.5 5" pos="-27.5 -12.5 0.5" rgba="0.0 0.0 0.5 1" />
                
                <geom conaffinity="1" type="box" name="wall_3_2" size="2.5 2.5 5" pos="-27.5 -7.5 0.5" rgba="0.0 0.0 0.5 1" />
                
                <geom conaffinity="1" type="box" name="wall_3_5" size="2.5 2.5 5" pos="-27.5 7.5 0.5" rgba="0.0 0.0 0.5 1" />
                
                <geom conaffinity="1" type="box" name="wall_3_6" size="2.5 2.5 5" pos="-27.5 12.5 0.5" rgba="0.0 0.0 0.5 1" />
                
                <geom conaffinity="1" type="box" name="wall_3_7" size="2.5 2.5 5" pos="-27.5 17.5 0.5" rgba="0.0 0.0 0.5 1" />
                
                <geom conaffinity="1" type="box" name="wall_3_10" size="2.5 2.5 5" pos="-27.5 32.5 0.5" rgba="0.0 0.0 0.5 1" />
                
                <geom conaffinity="1" type="box" name="wall_4_0" size="2.5 2.5 5" pos="-22.5 -17.5 0.5" rgba="0.0 0.0 0.5 1" />
                
                <geom conaffinity="1" type="box" name="wall_4_1" size="2.5 2.5 5" pos="-22.5 -12.5 0.5" rgba="0.0 0.0 0.5 1" />
                
                <geom conaffinity="1" type="box" name="wall_4_2" size="2.5 2.5 5" pos="-22.5 -7.5 0.5" rgba="0.0 0.0 0.5 1" />
                
                <geom conaffinity="1" type="box" name="wall_4_5" size="2.5 2.5 5" pos="-22.5 7.5 0.5" rgba="0.0 0.0 0.5 1" />
                
                <geom conaffinity="1" type="box" name="wall_4_6" size="2.5 2.5 5" pos="-22.5 12.5 0.5" rgba="0.0 0.0 0.5 1" />
                
                <geom conaffinity="1" type="box" name="wall_4_7" size="2.5 2.5 5" pos="-22.5 17.5 0.5" rgba="0.0 0.0 0.5 1" />
                
                <geom conaffinity="1" type="box" name="wall_4_10" size="2.5 2.5 5" pos="-22.5 32.5 0.5" rgba="0.0 0.0 0.5 1" />
                
                <geom conaffinity="1" type="box" name="wall_5_0" size="2.5 2.5 5" pos="-17.5 -17.5 0.5" rgba="0.0 0.0 0.5 1" />
                
                <geom conaffinity="1" type="box" name="wall_5_1" size="2.5 2.5 5" pos="-17.5 -12.5 0.5" rgba="0.0 0.0 0.5 1" />
                
                <geom conaffinity="1" type="box" name="wall_5_2" size="2.5 2.5 5" pos="-17.5 -7.5 0.5" rgba="0.0 0.0 0.5 1" />
                
                <geom conaffinity="1" type="box" name="wall_5_5" size="2.5 2.5 5" pos="-17.5 7.5 0.5" rgba="0.0 0.0 0.5 1" />
                
                <geom conaffinity="1" type="box" name="wall_5_6" size="2.5 2.5 5" pos="-17.5 12.5 0.5" rgba="0.0 0.0 0.5 1" />
                
                <geom conaffinity="1" type="box" name="wall_5_7" size="2.5 2.5 5" pos="-17.5 17.5 0.5" rgba="0.0 0.0 0.5 1" />
                
                <geom conaffinity="1" type="box" name="wall_5_10" size="2.5 2.5 5" pos="-17.5 32.5 0.5" rgba="0.0 0.0 0.5 1" />
                
                <geom conaffinity="1" type="box" name="wall_6_0" size="2.5 2.5 5" pos="-12.5 -17.5 0.5" rgba="0.0 0.0 0.5 1" />
                
                <geom conaffinity="1" type="box" name="wall_6_1" size="2.5 2.5 5" pos="-12.5 -12.5 0.5" rgba="0.0 0.0 0.5 1" />
                
                <geom conaffinity="1" type="box" name="wall_6_2" size="2.5 2.5 5" pos="-12.5 -7.5 0.5" rgba="0.0 0.0 0.5 1" />
                
                <geom conaffinity="1" type="box" name="wall_6_5" size="2.5 2.5 5" pos="-12.5 7.5 0.5" rgba="0.0 0.0 0.5 1" />
                
                <geom conaffinity="1" type="box" name="wall_6_6" size="2.5 2.5 5" pos="-12.5 12.5 0.5" rgba="0.0 0.0 0.5 1" />
                
                <geom conaffinity="1" type="box" name="wall_6_7" size="2.5 2.5 5" pos="-12.5 17.5 0.5" rgba="0.0 0.0 0.5 1" />
                
                <geom conaffinity="1" type="box" name="wall_6_10" size="2.5 2.5 5" pos="-12.5 32.5 0.5" rgba="0.0 0.0 0.5 1" />
                
                <geom conaffinity="1" type="box" name="wall_7_0" size="2.5 2.5 5" pos="-7.5 -17.5 0.5" rgba="0.0 0.0 0.5 1" />
                
                <geom conaffinity="1" type="box" name="wall_7_1" size="2.5 2.5 5" pos="-7.5 -12.5 0.5" rgba="0.0 0.0 0.5 1" />
                
                <geom conaffinity="1" type="box" name="wall_7_2" size="2.5 2.5 5" pos="-7.5 -7.5 0.5" rgba="0.0 0.0 0.5 1" />
                
                <geom conaffinity="1" type="box" name="wall_7_5" size="2.5 2.5 5" pos="-7.5 7.5 0.5" rgba="0.0 0.0 0.5 1" />
                
                <geom conaffinity="1" type="box" name="wall_7_6" size="2.5 2.5 5" pos="-7.5 12.5 0.5" rgba="0.0 0.0 0.5 1" />
                
                <geom conaffinity="1" type="box" name="wall_7_7" size="2.5 2.5 5" pos="-7.5 17.5 0.5" rgba="0.0 0.0 0.5 1" />
                
                <geom conaffinity="1" type="box" name="wall_7_10" size="2.5 2.5 5" pos="-7.5 32.5 0.5" rgba="0.0 0.0 0.5 1" />
                
                <geom conaffinity="1" type="box" name="wall_8_0" size="2.5 2.5 5" pos="-2.5 -17.5 0.5" rgba="0.0 0.0 0.5 1" />
                
                <geom conaffinity="1" type="box" name="wall_8_1" size="2.5 2.5 5" pos="-2.5 -12.5 0.5" rgba="0.0 0.0 0.5 1" />
                
                <geom conaffinity="1" type="box" name="wall_8_2" size="2.5 2.5 5" pos="-2.5 -7.5 0.5" rgba="0.0 0.0 0.5 1" />
                
                <geom conaffinity="1" type="box" name="wall_8_10" size="2.5 2.5 5" pos="-2.5 32.5 0.5" rgba="0.0 0.0 0.5 1" />
                
                <geom conaffinity="1" type="box" name="wall_9_0" size="2.5 2.5 5" pos="2.5 -17.5 0.5" rgba="0.0 0.0 0.5 1" />
                
                <geom conaffinity="1" type="box" name="wall_9_1" size="2.5 2.5 5" pos="2.5 -12.5 0.5" rgba="0.0 0.0 0.5 1" />
                
                <geom conaffinity="1" type="box" name="wall_9_2" size="2.5 2.5 5" pos="2.5 -7.5 0.5" rgba="0.0 0.0 0.5 1" />
                
                <geom conaffinity="1" type="box" name="wall_9_10" size="2.5 2.5 5" pos="2.5 32.5 0.5" rgba="0.0 0.0 0.5 1" />
                
                <geom conaffinity="1" type="box" name="wall_10_0" size="2.5 2.5 5" pos="7.5 -17.5 0.5" rgba="0.0 0.0 0.5 1" />
                
                <geom conaffinity="1" type="box" name="wall_10_1" size="2.5 2.5 5" pos="7.5 -12.5 0.5" rgba="0.0 0.0 0.5 1" />
                
                <geom conaffinity="1" type="box" name="wall_10_2" size="2.5 2.5 5" pos="7.5 -7.5 0.5" rgba="0.0 0.0 0.5 1" />
                
                <geom conaffinity="1" type="box" name="wall_10_3" size="2.5 2.5 5" pos="7.5 -2.5 0.5" rgba="0.0 0.0 0.5 1" />
                
                <geom conaffinity="1" type="box" name="wall_10_4" size="2.5 2.5 5" pos="7.5 2.5 0.5" rgba="0.0 0.0 0.5 1" />
                
                <geom conaffinity="1" type="box" name="wall_10_5" size="2.5 2.5 5" pos="7.5 7.5 0.5" rgba="0.0 0.0 0.5 1" />
                
                <geom conaffinity="1" type="box" name="wall_10_6" size="2.5 2.5 5" pos="7.5 12.5 0.5" rgba="0.0 0.0 0.5 1" />
                
                <geom conaffinity="1" type="box" name="wall_10_7" size="2.5 2.5 5" pos="7.5 17.5 0.5" rgba="0.0 0.0 0.5 1" />
                
                <geom conaffinity="1" type="box" name="wall_10_8" size="2.5 2.5 5" pos="7.5 22.5 0.5" rgba="0.0 0.0 0.5 1" />
                
                <geom conaffinity="1" type="box" name="wall_10_9" size="2.5 2.5 5" pos="7.5 27.5 0.5" rgba="0.0 0.0 0.5 1" />
                
                <geom conaffinity="1" type="box" name="wall_10_10" size="2.5 2.5 5" pos="7.5 32.5 0.5" rgba="0.0 0.0 0.5 1" /> -->

    <light cutoff="100" diffuse="1 1 1" dir="-0 0 -1.3" directional="true" exponent="1" pos="0 0 1.3" specular=".1 .1 .1"/>
    <geom conaffinity="1" condim="3" material="MatPlane" name="floor" pos="0 0 0" rgba="0.8 0.9 0.8 1" size="400 400 400" type="plane"/>
    <body name="torso" pos="0 0 0.75">
      <camera name="track" mode="trackcom" pos="0 -3 0.3" xyaxes="1 0 0 0 0 1"/>
      <geom name="torso_geom" pos="0 0 0" size="0.25" type="sphere"/>
      <joint armature="0" damping="0" limited="false" margin="0.01" name="root" pos="0 0 0" type="free"/>
      <body name="front_left_leg" pos="0 0 0">
        <geom fromto="0.0 0.0 0.0 0.2 0.2 0.0" name="aux_1_geom" size="0.08" type="capsule"/>
        <body name="aux_1" pos="0.2 0.2 0">
          <joint axis="0 0 1" name="hip_1" pos="0.0 0.0 0.0" range="-30 30" type="hinge"/>
          <geom fromto="0.0 0.0 0.0 0.2 0.2 0.0" name="left_leg_geom" size="0.08" type="capsule"/>
          <body pos="0.2 0.2 0">
            <joint axis="-1 1 0" name="ankle_1" pos="0.0 0.0 0.0" range="30 70" type="hinge"/>
            <geom fromto="0.0 0.0 0.0 0.4 0.4 0.0" name="left_ankle_geom" size="0.08" type="capsule"/>
          </body>
        </body>
      </body>
      <body name="front_right_leg" pos="0 0 0">
        <geom fromto="0.0 0.0 0.0 -0.2 0.2 0.0" name="aux_2_geom" size="0.08" type="capsule"/>
        <body name="aux_2" pos="-0.2 0.2 0">
          <joint axis="0 0 1" name="hip_2" pos="0.0 0.0 0.0" range="-30 30" type="hinge"/>
          <geom fromto="0.0 0.0 0.0 -0.2 0.2 0.0" name="right_leg_geom" size="0.08" type="capsule"/>
          <body pos="-0.2 0.2 0">
            <joint axis="1 1 0" name="ankle_2" pos="0.0 0.0 0.0" range="-70 -30" type="hinge"/>
            <geom fromto="0.0 0.0 0.0 -0.4 0.4 0.0" name="right_ankle_geom" size="0.08" type="capsule"/>
          </body>
        </body>
      </body>
      <body name="back_leg" pos="0 0 0">
        <geom fromto="0.0 0.0 0.0 -0.2 -0.2 0.0" name="aux_3_geom" size="0.08" type="capsule"/>
        <body name="aux_3" pos="-0.2 -0.2 0">
          <joint axis="0 0 1" name="hip_3" pos="0.0 0.0 0.0" range="-30 30" type="hinge"/>
          <geom fromto="0.0 0.0 0.0 -0.2 -0.2 0.0" name="back_leg_geom" size="0.08" type="capsule"/>
          <body pos="-0.2 -0.2 0">
            <joint axis="-1 1 0" name="ankle_3" pos="0.0 0.0 0.0" range="-70 -30" type="hinge"/>
            <geom fromto="0.0 0.0 0.0 -0.4 -0.4 0.0" name="third_ankle_geom" size="0.08" type="capsule"/>
          </body>
        </body>
      </body>
      <body name="right_back_leg" pos="0 0 0">
        <geom fromto="0.0 0.0 0.0 0.2 -0.2 0.0" name="aux_4_geom" size="0.08" type="capsule"/>
        <body name="aux_4" pos="0.2 -0.2 0">
          <joint axis="0 0 1" name="hip_4" pos="0.0 0.0 0.0" range="-30 30" type="hinge"/>
          <geom fromto="0.0 0.0 0.0 0.2 -0.2 0.0" name="rightback_leg_geom" size="0.08" type="capsule"/>
          <body pos="0.2 -0.2 0">
            <joint axis="1 1 0" name="ankle_4" pos="0.0 0.0 0.0" range="30 70" type="hinge"/>
            <geom fromto="0.0 0.0 0.0 0.4 -0.4 0.0" name="fourth_ankle_geom" size="0.08" type="capsule"/>
          </body>
        </body>
      </body>
    </body>
  </worldbody>
  <actuator>
    <motor ctrllimited="true" ctrlrange="-1.0 1.0" joint="hip_4"   gear="140"/>
    <motor ctrllimited="true" ctrlrange="-1.0 1.0" joint="ankle_4" gear="140"/>
    <motor ctrllimited="true" ctrlrange="-1.0 1.0" joint="hip_1"   gear="140"/>
    <motor ctrllimited="true" ctrlrange="-1.0 1.0" joint="ankle_1" gear="140"/>
    <motor ctrllimited="true" ctrlrange="-1.0 1.0" joint="hip_2"   gear="140"/>
    <motor ctrllimited="true" ctrlrange="-1.0 1.0" joint="ankle_2" gear="140"/>
    <motor ctrllimited="true" ctrlrange="-1.0 1.0" joint="hip_3"   gear="140"/>
    <motor ctrllimited="true" ctrlrange="-1.0 1.0" joint="ankle_3" gear="140"/>
  </actuator>
</mujoco>
